<?xml version='1.0' encoding='utf-8'?>
<robot name="frog">
    <link name="base-link">
        <inertial>
            <origin xyz="-0.0026207604634829068 0.0 0.018351499677090002" rpy="0.0 0.0 0.0" />
            <mass value="0.10999864928459796" />
            <inertia ixx="7.340039646891687e-06" iyy="1.4893708283392455e-05" izz="1.4902103626545398e-05" ixy="-1.0318856880076055e-19" iyz="7.717249950189853e-17" ixz="-4.828087799349512e-20" />
        </inertial>
        <visual name="base-link_visual">
            <origin xyz="0.0 0.0 0.0" rpy="0.0 0.0 0.0" />
            <geometry>
                <mesh filename="meshes/base-link.stl" scale="0.001 0.001 0.001" />
            </geometry>
        </visual>
        <collision name="base-link_collision">
            <origin xyz="0.0 0.0 0.0" rpy="0.0 0.0 0.0" />
            <geometry>
                <mesh filename="meshes/base-link.stl" scale="0.001 0.001 0.001" />
            </geometry>
        </collision>
    </link>
    <link name="left-front-up">
        <inertial>
            <origin xyz="-4.634828121297119e-10 -0.007393890422509251 -0.0024999998509883914" rpy="0.0 -0.0 0.0" />
            <mass value="0.002776807258817609" />
            <inertia ixx="5.2761584057436437e-08" iyy="1.1482366475279717e-08" izz="5.2673920287642635e-08" ixy="0.0" iyz="-2.6469779601696886e-23" ixz="1.0587911840678754e-22" />
        </inertial>
        <visual name="left-front-up_visual">
            <origin xyz="0.012516524678779402 -0.025382981763435734 -0.015000000000000003" rpy="-1.5707963267948966 -0.0 0.0" />
            <geometry>
                <mesh filename="meshes/left-front-up.stl" scale="0.001 0.001 0.001" />
            </geometry>
        </visual>
        <collision name="left-front-up_collision">
            <origin xyz="0.012516524678779402 -0.025382981763435734 -0.015000000000000003" rpy="-1.5707963267948966 -0.0 0.0" />
            <geometry>
                <mesh filename="meshes/left-front-up.stl" scale="0.001 0.001 0.001" />
            </geometry>
        </collision>
    </link>
    <link name="left-front-down">
        <inertial>
            <origin xyz="-8.964127323762838e-08 -0.00479174435203383 1.4901161082825354e-10" rpy="0.0 -0.0 0.0" />
            <mass value="0.0011165908230702513" />
            <inertia ixx="5.511645420592039e-09" iyy="4.695817732338336e-09" izz="5.712175837701653e-09" ixy="4.586299848312799e-13" iyz="0.0" ixz="-1.3234889800848443e-23" />
        </inertial>
        <visual name="left-front-down_visual">
            <origin xyz="0.012516524678779402 -0.00688298176343573 -0.012500000000000004" rpy="-1.5707963267948966 -0.0 0.0" />
            <geometry>
                <mesh filename="meshes/left-front-down.stl" scale="0.001 0.001 0.001" />
            </geometry>
        </visual>
        <collision name="left-front-down_collision">
            <origin xyz="0.012516524678779402 -0.00688298176343573 -0.012500000000000004" rpy="-1.5707963267948966 -0.0 0.0" />
            <geometry>
                <mesh filename="meshes/left-front-down.stl" scale="0.001 0.001 0.001" />
            </geometry>
        </collision>
    </link>
    <link name="left-back-up">
        <inertial>
            <origin xyz="2.6392760385068882e-05 -0.007090730495237867 -0.0034999998509883867" rpy="0.0 -0.0 0.0" />
            <mass value="0.006848741329917298" />
            <inertia ixx="1.4111432227979106e-07" iyy="7.184207980953931e-08" izz="1.570250145616731e-07" ixy="-1.6023981133610973e-11" iyz="-3.705769144237564e-22" ixz="-1.0587911840678754e-22" />
        </inertial>
        <visual name="left-back-up_visual">
            <origin xyz="-0.008000000575241526 -0.01799999650728049 -0.017" rpy="-1.5707963267948966 -0.0 0.0" />
            <geometry>
                <mesh filename="meshes/left-back-up.stl" scale="0.001 0.001 0.001" />
            </geometry>
        </visual>
        <collision name="left-back-up_collision">
            <origin xyz="-0.008000000575241526 -0.01799999650728049 -0.017" rpy="-1.5707963267948966 -0.0 0.0" />
            <geometry>
                <mesh filename="meshes/left-back-up.stl" scale="0.001 0.001 0.001" />
            </geometry>
        </collision>
    </link>
    <link name="left-back-down">
        <inertial>
            <origin xyz="3.2254111126395202e-09 -0.009110490799856756 1.490116086078075e-10" rpy="0.0 -0.0 0.0" />
            <mass value="0.005555232688979731" />
            <inertia ixx="8.400236336369896e-08" iyy="6.228937278740522e-08" izz="1.0165161030221345e-07" ixy="2.6469779601696886e-23" iyz="1.5881867761018131e-22" ixz="0.0" />
        </inertial>
        <visual name="left-back-down_visual">
            <origin xyz="-0.008026040575241526 -0.0035509965072804883 -0.013500000000000002" rpy="-1.5707963267948966 -0.0 0.0" />
            <geometry>
                <mesh filename="meshes/left-back-down.stl" scale="0.001 0.001 0.001" />
            </geometry>
        </visual>
        <collision name="left-back-down_collision">
            <origin xyz="-0.008026040575241526 -0.0035509965072804883 -0.013500000000000002" rpy="-1.5707963267948966 -0.0 0.0" />
            <geometry>
                <mesh filename="meshes/left-back-down.stl" scale="0.001 0.001 0.001" />
            </geometry>
        </collision>
    </link>
    <link name="right-front-up">
        <inertial>
            <origin xyz="-4.6348281435015793e-10 0.007393890571520876 -0.002499999850988388" rpy="0.0 -0.0 0.0" />
            <mass value="0.002776807258817609" />
            <inertia ixx="5.2761584057436384e-08" iyy="1.1482366475279717e-08" izz="5.2673920287642635e-08" ixy="0.0" iyz="-2.6469779601696886e-23" ixz="-5.293955920339377e-23" />
        </inertial>
        <visual name="right-front-up_visual">
            <origin xyz="0.0125165246787794 0.02538298191244736 0.010000000298023224" rpy="1.5707963267948966 -0.0 0.0" />
            <geometry>
                <mesh filename="meshes/right-front-up.stl" scale="0.001 0.001 0.001" />
            </geometry>
        </visual>
        <collision name="right-front-up_collision">
            <origin xyz="0.0125165246787794 0.02538298191244736 0.010000000298023224" rpy="1.5707963267948966 -0.0 0.0" />
            <geometry>
                <mesh filename="meshes/right-front-up.stl" scale="0.001 0.001 0.001" />
            </geometry>
        </collision>
    </link>
    <link name="right-back-up">
        <inertial>
            <origin xyz="2.6392760385068882e-05 0.0070907306442494844 -0.003499999850988389" rpy="0.0 -0.0 0.0" />
            <mass value="0.006848741329917298" />
            <inertia ixx="1.4111432227979095e-07" iyy="7.184207980953931e-08" izz="1.5702501456167288e-07" ixy="1.6023981133505094e-11" iyz="-3.705769144237564e-22" ixz="0.0" />
        </inertial>
        <visual name="right-back-up_visual">
            <origin xyz="-0.008000000575241526 0.017999996656292108 0.010000000298023224" rpy="1.5707963267948966 -0.0 0.0" />
            <geometry>
                <mesh filename="meshes/right-back-up.stl" scale="0.001 0.001 0.001" />
            </geometry>
        </visual>
        <collision name="right-back-up_collision">
            <origin xyz="-0.008000000575241526 0.017999996656292108 0.010000000298023224" rpy="1.5707963267948966 -0.0 0.0" />
            <geometry>
                <mesh filename="meshes/right-back-up.stl" scale="0.001 0.001 0.001" />
            </geometry>
        </collision>
    </link>
    <link name="right-back-down">
        <inertial>
            <origin xyz="3.2254111126395202e-09 -0.009110490948868373 -0.003500000149011614" rpy="0.0 -0.0 0.0" />
            <mass value="0.005555232688979731" />
            <inertia ixx="8.400236336369885e-08" iyy="6.228937278740522e-08" izz="1.0165161030221345e-07" ixy="2.6469779601696886e-23" iyz="2.117582368135751e-22" ixz="0.0" />
        </inertial>
        <visual name="right-back-down_visual">
            <origin xyz="-0.008026040575241526 -0.003550996656292107 -0.017000000298023225" rpy="-1.5707963267948966 -0.0 0.0" />
            <geometry>
                <mesh filename="meshes/right-back-down.stl" scale="0.001 0.001 0.001" />
            </geometry>
        </visual>
        <collision name="right-back-down_collision">
            <origin xyz="-0.008026040575241526 -0.003550996656292107 -0.017000000298023225" rpy="-1.5707963267948966 -0.0 0.0" />
            <geometry>
                <mesh filename="meshes/right-back-down.stl" scale="0.001 0.001 0.001" />
            </geometry>
        </collision>
    </link>
    <link name="right-front-down">
        <inertial>
            <origin xyz="-8.964127323984883e-08 -0.004791744501045455 -0.002500000149011611" rpy="0.0 -0.0 0.0" />
            <mass value="0.0011165908230702513" />
            <inertia ixx="5.511645420592039e-09" iyy="4.695817732338389e-09" izz="5.71217583770168e-09" ixy="4.586299848577497e-13" iyz="0.0" ixz="-3.970466940254533e-23" />
        </inertial>
        <visual name="right-front-down_visual">
            <origin xyz="0.0125165246787794 -0.006882981912447356 -0.015000000298023224" rpy="-1.5707963267948966 -0.0 0.0" />
            <geometry>
                <mesh filename="meshes/right-front-down.stl" scale="0.001 0.001 0.001" />
            </geometry>
        </visual>
        <collision name="right-front-down_collision">
            <origin xyz="0.0125165246787794 -0.006882981912447356 -0.015000000298023224" rpy="-1.5707963267948966 -0.0 0.0" />
            <geometry>
                <mesh filename="meshes/right-front-down.stl" scale="0.001 0.001 0.001" />
            </geometry>
        </collision>
    </link>
    <joint name="base-link_left-front-up" type="revolute">
        <origin xyz="-0.01212076 -0.011000000000000001 0.013355980000000002" rpy="1.5707963267948966 -0.0 0.0" />
        <parent link="base-link" />
        <child link="left-front-up" />
        <axis xyz="0.0 0.0 1.0" />
        <limit lower="-1.570796" upper="1.570796" effort="1000000" velocity="1000000" />
    </joint>
    <joint name="left-front-up_left-front-down" type="revolute">
        <origin xyz="0.0 -0.0125 -0.0025000000000000014" rpy="0.0 -0.0 0.0" />
        <parent link="left-front-up" />
        <child link="left-front-down" />
        <axis xyz="0.0 0.0 1.0" />
        <limit lower="-1.570796" upper="1.570796" effort="1000000" velocity="1000000" />
    </joint>
    <joint name="base-link_left-back-up" type="revolute">
        <origin xyz="0.00687924 -0.011000000000000001 0.013355980000000002" rpy="1.5707963267948966 -0.0 0.0" />
        <parent link="base-link" />
        <child link="left-back-up" />
        <axis xyz="0.0 0.0 1.0" />
        <limit lower="-1.570796" upper="1.570796" effort="1000000" velocity="1000000" />
    </joint>
    <joint name="left-back-up_left-back-down" type="revolute">
        <origin xyz="2.6040000000000506e-05 -0.010449000000000002 -0.003500000000000001" rpy="0.0 -0.0 0.0" />
        <parent link="left-back-up" />
        <child link="left-back-down" />
        <axis xyz="0.0 0.0 1.0" />
        <limit lower="-1.570796" upper="1.570796" effort="1000000" velocity="1000000" />
    </joint>
    <joint name="base-link_right-back-up" type="revolute">
        <origin xyz="0.00687924 0.011000000000000001 0.013355980000000002" rpy="-1.5707963267948966 -0.0 0.0" />
        <parent link="base-link" />
        <child link="right-back-up" />
        <axis xyz="0.0 0.0 1.0" />
        <limit lower="-1.570796" upper="1.570796" effort="1000000" velocity="1000000" />
    </joint>
    <joint name="right-back-up_right-back-down" type="revolute">
        <origin xyz="2.6040000000000506e-05 0.010449000000000002 -0.007000000000000001" rpy="3.141592653589793 -0.0 0.0" />
        <parent link="right-back-up" />
        <child link="right-back-down" />
        <axis xyz="0.0 0.0 1.0" />
        <limit lower="-1.570796" upper="1.570796" effort="1000000" velocity="1000000" />
    </joint>
    <joint name="base-link_right-front-up" type="revolute">
        <origin xyz="-0.01212076 0.011000000000000001 0.013355980000000002" rpy="-1.5707963267948966 -0.0 0.0" />
        <parent link="base-link" />
        <child link="right-front-up" />
        <axis xyz="0.0 0.0 1.0" />
        <limit lower="-1.570796" upper="1.570796" effort="1000000" velocity="1000000" />
    </joint>
    <joint name="right-front-up_right-front-down" type="revolute">
        <origin xyz="0.0 0.0125 -0.005000000000000001" rpy="3.141592653589793 -0.0 0.0" />
        <parent link="right-front-up" />
        <child link="right-front-down" />
        <axis xyz="0.0 0.0 1.0" />
        <limit lower="-1.570796" upper="1.570796" effort="1000000" velocity="1000000" />
    </joint>
</robot>