<mujoco model="frog">
  <compiler angle="radian" coordinate="local" inertiafromgeom="true" settotalmass="5"/>
  <default>
    <joint armature=".1" damping=".01" limited="true" solimplimit="0 .8 .03" solreflimit=".02 1" stiffness="8"/>
    <geom conaffinity="0" condim="3" contype="1" friction=".4 .1 .1" rgba="0.2 0.8 0.2 1" solimp="0.0 0.8 0.01" solref="0.02 1"/>
    <motor ctrllimited="true" ctrlrange="-1 1"/>
  </default>
  <size nstack="300000"/>
  <option gravity="0 0 -9.81" timestep="0.01"/>
  <asset>
    <texture builtin="gradient" height="100" rgb1="1 1 1" rgb2="0 0 0" type="skybox" width="100"/>
    <material name="geom" rgba="0.2 0.8 0.2 1"/>
  </asset>
  <worldbody>
    <light cutoff="100" diffuse="1 1 1" dir="-0 0 -1.3" directional="true" exponent="1" pos="0 0 1.3" specular=".1 .1 .1"/>
    <geom type="plane" pos="0 0 0" size="10 10 0.1" rgba="0.8 0.9 0.8 1"/>
    <body name="torso" pos="0 0 0.4">
      <joint name="rootx" type="slide" axis="1 0 0"/>
      <joint name="rootz" type="slide" axis="0 0 1"/>
      <joint name="rooty" type="hinge" axis="0 1 0"/>
      <geom type="capsule" fromto="-.3 0 0 .3 0 0" size="0.05"/>

      <!-- Left Front Leg -->
      <body name="lf_upper" pos="0.25 0.2 0">
        <joint name="lf_thigh" type="hinge" axis="0 1 0" range="-1 1"/>
        <geom type="capsule" fromto="0 0 0 0 0 -0.2" size="0.03"/>
        <body name="lf_lower" pos="0 0 -0.2">
          <joint name="lf_shin" type="hinge" axis="0 1 0" range="-1.2 0.5"/>
          <geom type="capsule" fromto="0 0 0 0 0 -0.15" size="0.025"/>
        </body>
      </body>

      <!-- Right Front Leg -->
      <body name="rf_upper" pos="0.25 -0.2 0">
        <joint name="rf_thigh" type="hinge" axis="0 1 0" range="-1 1"/>
        <geom type="capsule" fromto="0 0 0 0 0 -0.2" size="0.03"/>
        <body name="rf_lower" pos="0 0 -0.2">
          <joint name="rf_shin" type="hinge" axis="0 1 0" range="-1.2 0.5"/>
          <geom type="capsule" fromto="0 0 0 0 0 -0.15" size="0.025"/>
        </body>
      </body>

      <!-- Left Back Leg -->
      <body name="lb_upper" pos="-0.25 0.2 0">
        <joint name="lb_thigh" type="hinge" axis="0 1 0" range="-1 1"/>
        <geom type="capsule" fromto="0 0 0 0 0 -0.25" size="0.035"/>
        <body name="lb_lower" pos="0 0 -0.25">
          <joint name="lb_shin" type="hinge" axis="0 1 0" range="-1.2 0.5"/>
          <geom type="capsule" fromto="0 0 0 0 0 -0.2" size="0.03"/>
        </body>
      </body>

      <!-- Right Back Leg -->
      <body name="rb_upper" pos="-0.25 -0.2 0">
        <joint name="rb_thigh" type="hinge" axis="0 1 0" range="-1 1"/>
        <geom type="capsule" fromto="0 0 0 0 0 -0.25" size="0.035"/>
        <body name="rb_lower" pos="0 0 -0.25">
          <joint name="rb_shin" type="hinge" axis="0 1 0" range="-1.2 0.5"/>
          <geom type="capsule" fromto="0 0 0 0 0 -0.2" size="0.03"/>
        </body>
      </body>
    </body>
  </worldbody>

  <actuator>
    <motor joint="lf_thigh" gear="100"/>
    <motor joint="lf_shin" gear="80"/>
    <motor joint="rf_thigh" gear="100"/>
    <motor joint="rf_shin" gear="80"/>
    <motor joint="lb_thigh" gear="120"/>
    <motor joint="lb_shin" gear="90"/>
    <motor joint="rb_thigh" gear="120"/>
    <motor joint="rb_shin" gear="90"/>
  </actuator>
</mujoco>
